Workbook

Sheet Sayfa2
A1: Ocak | B1: 2025 | C1: Tarih | D1: Resmi Tatil
A2: Şubat | B2: 2026 | C2: 45658 | D2: Yılbaşı
A3: Mart | B3: 2027 | C3: 45745 | D3: Ramazan Bayramı Arifesi
A4: Nisan | B4: 2028 | C4: 45746 | D4: Ramazan Bayramı 1.gün
A5: Mayıs | B5: 2029 | C5: 45747 | D5: Ramazan Bayramı 2.gün
A6: Haziran | B6: 2030 | C6: 45748 | D6: Ramazan Bayramı 3.gün
A7: Temmuz | C7: 45770 | D7: Ulusal Egemenlik ve Çocuk Bayramı
A8: Ağustos | C8: 45778 | D8: Emek ve Dayanışma Günü
A9: Eylül | C9: 45796 | D9: Atatürk’ü Anma Gençlik ve Spor Bayramı
A10: Ekim | C10: 45813 | D10: Kurban Bayramı Arifesi
A11: Kasım | C11: 45814 | D11: Kurban Bayramı 1.gün
A12: Aralık | C12: 45815 | D12: Kurban Bayramı 2.gün
C13: 45816 | D13: Kurban Bayramı 3.gün
C14: 45817 | D14: Kurban Bayramı 4.gün
C15: 45853 | D15: Demokrasi ve Millî Birlik Günü
C16: 45899 | D16: Zafer Bayramı
C17: 45958 | D17: Cumhuriyet Bayramı Arifesi
C18: 45959 | D18: Cumhuriyet Bayramı
C19: 46022 | D19: Yılbaşı gecesi
C20: 45749 | D20: İdari İzin
C21: 45750 | D21: İdari İzin
C22: 45751 | D22: İdari İzin

Sheet Sayfa1
A1: ="Acil Radyoloji "&A2&" Nöbet Listesi" -> Acil Radyoloji Temmuz Nöbet Listesi | N1: 08:00-20:00 | O1: 20:00-08:00 | P1: Seyyar Grafi | Q1: Yazılan Mesai | R1: Yazılacak Mesai Saat | S1: Aylık Çalışılan Saat | T1: Fazla Mesai
A2: Temmuz | B2: 2025 | C2: 08:00 - 20:00 | G2: 20:00 - 08:00 | K2: Seyyar Grafi
A3: =DATE(B2,IF(A2="Ocak",1,IF(A2="Şubat",2,IF(A2="Mart",3,IF(A2="Nisan",4,IF(A2="Mayıs",5,IF(A2="Haziran",6,IF(A2="Temmuz",7,IF(A2="Ağustos",8,IF(A2="Eylül",9,IF(A2="Ekim",10,IF(A2="Kasım",11,IF(A2="Aralık",12,A2)))))))))))),1) -> 45839 | B3: =TEXT(A3,"gggg") -> Salı | C3: Emine İnan | D3: Emre T. Şahin | E3: Fatih Işık | F3: Ufuk Aydoğan | G3: Emine İnan | H3: Emre T. Şahin | I3: Fatih Işık | J3: Ufuk Aydoğan | K3: Arzu Şahin
A4: =IF(MONTH(A3+1)=MONTH(A3),A3+1,IF(MONTH(A3)+1<=12,DATE(YEAR(A3),MONTH(A3)+1,1),DATE(YEAR(A3)+1,1,1))) -> 45840 | B4: =TEXT(A4,"gggg") -> Çarşamba | C4: Selin Dal | D4: Kübra Gültaş | E4: Muhammet Tonkal | F4: Tuğçe Çalıkoğlu Eski | G4: Selin Dal | H4: Kübra Gültaş | I4: Muhammet Tonkal | J4: Tuğçe Çalıkoğlu Eski | K4: Arzu Şahin | M4: Cemil Oğuzcan | N4: =COUNTIF(C3:F33,M4) -> 7 | O4: =COUNTIF(G3:J33,M4) -> 8 | P4: =COUNTIF(K3:K33,M4) -> 2 | Q4: =((N4+O4)+P4) -> 17 | R4: =IFERROR(IF(VLOOKUP(M4,M35:T47,8,FALSE)="",D37,VLOOKUP(M4,M35:T47,8,FALSE)),NETWORKDAYS.INTL(A3,DATE(YEAR(A3),MONTH(A3)+1,1)-1,1,Sayfa2!C2:C30)*7) -> 154 | S4: =(N4*12)+(O4*12)+(P4*7) -> 194 | T4: =IF(S4-R4<0,0,(S4-R4)) -> 40
A5: =IF(MONTH(A4+1)=MONTH(A4),A4+1,IF(MONTH(A4)+1<=12,DATE(YEAR(A4),MONTH(A4)+1,1),DATE(YEAR(A4)+1,1,1))) -> 45841 | B5: =TEXT(A5,"gggg") -> Perşembe | C5: Melek Ünal | D5: Emre T. Şahin | F5: Cemil Oğuzcan | G5: Ömer Demir | H5: Emre T. Şahin | I5: Melek Ünal | J5: Cemil Oğuzcan | K5: Arzu Şahin | M5: Burak Şan | N5: =COUNTIF(C3:F33,M5) -> 4 | O5: =COUNTIF(G3:J33,M5) -> 4 | P5: =COUNTIF(K3:K33,M5) -> 2 | Q5: =((N5+O5)+P5) -> 10 | R5: =IFERROR(IF(VLOOKUP(M5,M35:T47,8,FALSE)="",D37,VLOOKUP(M5,M35:T47,8,FALSE)),NETWORKDAYS.INTL(A3,DATE(YEAR(A3),MONTH(A3)+1,1)-1,1,Sayfa2!C2:C30)*7) -> 91 | S5: =(N5*12)+(O5*12)+(P5*7) -> 110 | T5: =IF(S5-R5<0,0,(S5-R5)) -> 19
A6: =IF(MONTH(A5+1)=MONTH(A5),A5+1,IF(MONTH(A5)+1<=12,DATE(YEAR(A5),MONTH(A5)+1,1),DATE(YEAR(A5)+1,1,1))) -> 45842 | B6: =TEXT(A6,"gggg") -> Cuma | C6: Fatih Işık | D6: Ahmet Yılmaz | E6: İsmail Sarıgüzel | F6: Ufuk Aydoğan | G6: Fatih Işık | H6: Ahmet Yılmaz | I6: İsmail Sarıgüzel | J6: Ufuk Aydoğan | K6: Arzu Şahin | M6: Muhammet Tonkal | N6: =COUNTIF(C3:F33,M6) -> 6 | O6: =COUNTIF(G3:J33,M6) -> 7 | P6: =COUNTIF(K3:K33,M6) -> 0 | Q6: =((N6+O6)+P6) -> 13 | R6: =IFERROR(IF(VLOOKUP(M6,M35:T47,8,FALSE)="",D37,VLOOKUP(M6,M35:T47,8,FALSE)),NETWORKDAYS.INTL(A3,DATE(YEAR(A3),MONTH(A3)+1,1)-1,1,Sayfa2!C2:C30)*7) -> 133 | S6: =(N6*12)+(O6*12)+(P6*7) -> 156 | T6: =IF(S6-R6<0,0,(S6-R6)) -> 23
A7: =IF(MONTH(A6+1)=MONTH(A6),A6+1,IF(MONTH(A6)+1<=12,DATE(YEAR(A6),MONTH(A6)+1,1),DATE(YEAR(A6)+1,1,1))) -> 45843 | B7: =TEXT(A7,"gggg") -> Cumartesi | C7: Muhammet Tonkal | D7: Melek Ünal | E7: Fevzi Karahan | F7: Dilek Buzakoğlu | G7: Muhammet Tonkal | H7: Melek Ünal | I7: Kübra Gültaş | J7: Dilek Buzakoğlu | K7: Cemil Oğuzcan | M7: Hakkı Tuncer | N7: =COUNTIF(C3:F33,M7) -> 8 | O7: =COUNTIF(G3:J33,M7) -> 8 | P7: =COUNTIF(K3:K33,M7) -> 0 | Q7: =((N7+O7)+P7) -> 16 | R7: =IFERROR(IF(VLOOKUP(M7,M35:T47,8,FALSE)="",D37,VLOOKUP(M7,M35:T47,8,FALSE)),NETWORKDAYS.INTL(A3,DATE(YEAR(A3),MONTH(A3)+1,1)-1,1,Sayfa2!C2:C30)*7) -> 154 | S7: =(N7*12)+(O7*12)+(P7*7) -> 192 | T7: =IF(S7-R7<0,0,(S7-R7)) -> 38
A8: =IF(MONTH(A7+1)=MONTH(A7),A7+1,IF(MONTH(A7)+1<=12,DATE(YEAR(A7),MONTH(A7)+1,1),DATE(YEAR(A7)+1,1,1))) -> 45844 | B8: =TEXT(A8,"gggg") -> Pazar | C8: Selin Dal | D8: İsmail Sarıgüzel | E8: Şevval Demir | F8: Tuğçe Çalıkoğlu Eski | G8: Selin Dal | H8: İsmail Sarıgüzel | I8: Şevval Demir | J8: Tuğçe Çalıkoğlu Eski | K8: Fatih Işık | M8: Deniz Aslan | N8: =COUNTIF(C3:F33,M8) -> 3 | O8: =COUNTIF(G3:J33,M8) -> 4 | P8: =COUNTIF(K3:K33,M8) -> 0 | Q8: =((N8+O8)+P8) -> 7 | R8: =IFERROR(IF(VLOOKUP(M8,M35:T47,8,FALSE)="",D37,VLOOKUP(M8,M35:T47,8,FALSE)),NETWORKDAYS.INTL(A3,DATE(YEAR(A3),MONTH(A3)+1,1)-1,1,Sayfa2!C2:C30)*7) -> 84 | S8: =(N8*12)+(O8*12)+(P8*7) -> 84 | T8: =IF(S8-R8<0,0,(S8-R8)) -> 0
A9: =IF(MONTH(A8+1)=MONTH(A8),A8+1,IF(MONTH(A8)+1<=12,DATE(YEAR(A8),MONTH(A8)+1,1),DATE(YEAR(A8)+1,1,1))) -> 45845 | B9: =TEXT(A9,"gggg") -> Pazartesi | C9: Ufuk Aydoğan | D9: Kübra Gültaş | E9: Ahmet Yılmaz | F9: Emre T. Şahin | G9: Ufuk Aydoğan | H9: Kübra Gültaş | I9: Ahmet Yılmaz | J9: Emre T. Şahin | K9: Arzu Şahin | M9: Melek Ünal | N9: =COUNTIF(C3:F33,M9) -> 8 | O9: =COUNTIF(G3:J33,M9) -> 6 | P9: =COUNTIF(K3:K33,M9) -> 0 | Q9: =((N9+O9)+P9) -> 14 | R9: =IFERROR(IF(VLOOKUP(M9,M35:T47,8,FALSE)="",D37,VLOOKUP(M9,M35:T47,8,FALSE)),NETWORKDAYS.INTL(A3,DATE(YEAR(A3),MONTH(A3)+1,1)-1,1,Sayfa2!C2:C30)*7) -> 154 | S9: =(N9*12)+(O9*12)+(P9*7) -> 168 | T9: =IF(S9-R9<0,0,(S9-R9)) -> 14
A10: =IF(MONTH(A9+1)=MONTH(A9),A9+1,IF(MONTH(A9)+1<=12,DATE(YEAR(A9),MONTH(A9)+1,1),DATE(YEAR(A9)+1,1,1))) -> 45846 | B10: =TEXT(A10,"gggg") -> Salı | C10: Fatih Işık | D10: Melek Ünal | E10: Emine İnan | F10: Cemil Oğuzcan | G10: Fatih Işık | H10: Mehmet Küskü | I10: Emine İnan | J10: Cemil Oğuzcan | K10: Arzu Şahin | M10: Ömer Demir | N10: =COUNTIF(C3:F33,M10) -> 6 | O10: =COUNTIF(G3:J33,M10) -> 7 | P10: =COUNTIF(K3:K33,M10) -> 0 | Q10: =((N10+O10)+P10) -> 13 | R10: =IFERROR(IF(VLOOKUP(M10,M35:T47,8,FALSE)="",D37,VLOOKUP(M10,M35:T47,8,FALSE)),NETWORKDAYS.INTL(A3,DATE(YEAR(A3),MONTH(A3)+1,1)-1,1,Sayfa2!C2:C30)*7) -> 154 | S10: =(N10*12)+(O10*12)+(P10*7) -> 156 | T10: =IF(S10-R10<0,0,(S10-R10)) -> 2
A11: =IF(MONTH(A10+1)=MONTH(A10),A10+1,IF(MONTH(A10)+1<=12,DATE(YEAR(A10),MONTH(A10)+1,1),DATE(YEAR(A10)+1,1,1))) -> 45847 | B11: =TEXT(A11,"gggg") -> Çarşamba | C11: Selin Dal | D11: Emre T. Şahin | E11: Şevval Demir | F11: Muhammet Tonkal | G11: Selin Dal | H11: Emre T. Şahin | I11: Şevval Demir | J11: Muhammet Tonkal | K11: Arzu Şahin | M11: Selin Dal | N11: =COUNTIF(C3:F33,M11) -> 7 | O11: =COUNTIF(G3:J33,M11) -> 6 | P11: =COUNTIF(K3:K33,M11) -> 0 | Q11: =((N11+O11)+P11) -> 13 | R11: =IFERROR(IF(VLOOKUP(M11,M35:T47,8,FALSE)="",D37,VLOOKUP(M11,M35:T47,8,FALSE)),NETWORKDAYS.INTL(A3,DATE(YEAR(A3),MONTH(A3)+1,1)-1,1,Sayfa2!C2:C30)*7) -> 154 | S11: =(N11*12)+(O11*12)+(P11*7) -> 156 | T11: =IF(S11-R11<0,0,(S11-R11)) -> 2
A12: =IF(MONTH(A11+1)=MONTH(A11),A11+1,IF(MONTH(A11)+1<=12,DATE(YEAR(A11),MONTH(A11)+1,1),DATE(YEAR(A11)+1,1,1))) -> 45848 | B12: =TEXT(A12,"gggg") -> Perşembe | C12: Ömer Demir | D12: Melek Ünal | E12: İsmail Sarıgüzel | F12: Dilek Buzakoğlu | G12: Ömer Demir | H12: Melek Ünal | I12: İsmail Sarıgüzel | J12: Dilek Buzakoğlu | K12: Arzu Şahin | M12: Ufuk Aydoğan | N12: =COUNTIF(C3:F33,M12) -> 7 | O12: =COUNTIF(G3:J33,M12) -> 7 | P12: =COUNTIF(K3:K33,M12) -> 1 | Q12: =((N12+O12)+P12) -> 15 | R12: =IFERROR(IF(VLOOKUP(M12,M35:T47,8,FALSE)="",D37,VLOOKUP(M12,M35:T47,8,FALSE)),NETWORKDAYS.INTL(A3,DATE(YEAR(A3),MONTH(A3)+1,1)-1,1,Sayfa2!C2:C30)*7) -> 154 | S12: =(N12*12)+(O12*12)+(P12*7) -> 175 | T12: =IF(S12-R12<0,0,(S12-R12)) -> 21
A13: =IF(MONTH(A12+1)=MONTH(A12),A12+1,IF(MONTH(A12)+1<=12,DATE(YEAR(A12),MONTH(A12)+1,1),DATE(YEAR(A12)+1,1,1))) -> 45849 | B13: =TEXT(A13,"gggg") -> Cuma | C13: Muhammet Tonkal | D13: Ufuk Aydoğan | E13: Tuğçe Çalıkoğlu Eski | F13: Cemil Oğuzcan | G13: Muhammet Tonkal | H13: Ufuk Aydoğan | I13: Tuğçe Çalıkoğlu Eski | J13: Cemil Oğuzcan | K13: Arzu Şahin | M13: Kübra Gültaş | N13: =COUNTIF(C3:F33,M13) -> 7 | O13: =COUNTIF(G3:J33,M13) -> 8 | P13: =COUNTIF(K3:K33,M13) -> 0 | Q13: =((N13+O13)+P13) -> 15 | R13: =IFERROR(IF(VLOOKUP(M13,M35:T47,8,FALSE)="",D37,VLOOKUP(M13,M35:T47,8,FALSE)),NETWORKDAYS.INTL(A3,DATE(YEAR(A3),MONTH(A3)+1,1)-1,1,Sayfa2!C2:C30)*7) -> 154 | S13: =(N13*12)+(O13*12)+(P13*7) -> 180 | T13: =IF(S13-R13<0,0,(S13-R13)) -> 26
A14: =IF(MONTH(A13+1)=MONTH(A13),A13+1,IF(MONTH(A13)+1<=12,DATE(YEAR(A13),MONTH(A13)+1,1),DATE(YEAR(A13)+1,1,1))) -> 45850 | B14: =TEXT(A14,"gggg") -> Cumartesi | C14: Selin Dal | D14: Mehmet Küskü | E14: Dilek Buzakoğlu | F14: Melek Ünal | G14: Selin Dal | H14: Mehmet Küskü | I14: Dilek Buzakoğlu | J14: Melek Ünal | K14: Arzu Şahin | M14: Emre T. Şahin | N14: =COUNTIF(C3:F33,M14) -> 7 | O14: =COUNTIF(G3:J33,M14) -> 6 | P14: =COUNTIF(K3:K33,M14) -> 0 | Q14: =((N14+O14)+P14) -> 13 | R14: =IFERROR(IF(VLOOKUP(M14,M35:T47,8,FALSE)="",D37,VLOOKUP(M14,M35:T47,8,FALSE)),NETWORKDAYS.INTL(A3,DATE(YEAR(A3),MONTH(A3)+1,1)-1,1,Sayfa2!C2:C30)*7) -> 136.4 | S14: =(N14*12)+(O14*12)+(P14*7) -> 156 | T14: =IF(S14-R14<0,0,(S14-R14)) -> 19.6
A15: =IF(MONTH(A14+1)=MONTH(A14),A14+1,IF(MONTH(A14)+1<=12,DATE(YEAR(A14),MONTH(A14)+1,1),DATE(YEAR(A14)+1,1,1))) -> 45851 | B15: =TEXT(A15,"gggg") -> Pazar | C15: Burak Şan | D15: Ahmet Yılmaz | E15: Şevval Demir | F15: Emine İnan | G15: Burak Şan | H15: Ahmet Yılmaz | I15: Şevval Demir | J15: Emine İnan | K15: Ufuk Aydoğan | M15: Şevval Demir | N15: =COUNTIF(C3:F33,M15) -> 5 | O15: =COUNTIF(G3:J33,M15) -> 5 | P15: =COUNTIF(K3:K33,M15) -> 0 | Q15: =((N15+O15)+P15) -> 10 | R15: =IFERROR(IF(VLOOKUP(M15,M35:T47,8,FALSE)="",D37,VLOOKUP(M15,M35:T47,8,FALSE)),NETWORKDAYS.INTL(A3,DATE(YEAR(A3),MONTH(A3)+1,1)-1,1,Sayfa2!C2:C30)*7) -> 121 | S15: =(N15*12)+(O15*12)+(P15*7) -> 120 | T15: =IF(S15-R15<0,0,(S15-R15)) -> 0
A16: =IF(MONTH(A15+1)=MONTH(A15),A15+1,IF(MONTH(A15)+1<=12,DATE(YEAR(A15),MONTH(A15)+1,1),DATE(YEAR(A15)+1,1,1))) -> 45852 | B16: =TEXT(A16,"gggg") -> Pazartesi | C16: Ömer Demir | D16: Melek Ünal | E16: Emre T. Şahin | F16: Cemil Oğuzcan | G16: Ömer Demir | H16: Melek Ünal | I16: Emre T. Şahin | J16: Cemil Oğuzcan | K16: İsmail Sarıgüzel | M16: Ahmet Yılmaz | N16: =COUNTIF(C3:F33,M16) -> 7 | O16: =COUNTIF(G3:J33,M16) -> 8 | P16: =COUNTIF(K3:K33,M16) -> 0 | Q16: =((N16+O16)+P16) -> 15 | R16: =IFERROR(IF(VLOOKUP(M16,M35:T47,8,FALSE)="",D37,VLOOKUP(M16,M35:T47,8,FALSE)),NETWORKDAYS.INTL(A3,DATE(YEAR(A3),MONTH(A3)+1,1)-1,1,Sayfa2!C2:C30)*7) -> 154 | S16: =(N16*12)+(O16*12)+(P16*7) -> 180 | T16: =IF(S16-R16<0,0,(S16-R16)) -> 26
A17: =IF(MONTH(A16+1)=MONTH(A16),A16+1,IF(MONTH(A16)+1<=12,DATE(YEAR(A16),MONTH(A16)+1,1),DATE(YEAR(A16)+1,1,1))) -> 45853 | B17: =TEXT(A17,"gggg") -> Salı | C17: Ufuk Aydoğan | D17: Hakkı Tuncer | E17: Ahmet Yılmaz | F17: Mehmet Küskü | G17: Ufuk Aydoğan | H17: Hakkı Tuncer | I17: Ahmet Yılmaz | J17: Mehmet Küskü | K17: Burak Şan | M17: Mehmet Küskü | N17: =COUNTIF(C3:F33,M17) -> 7 | O17: =COUNTIF(G3:J33,M17) -> 8 | P17: =COUNTIF(K3:K33,M17) -> 0 | Q17: =((N17+O17)+P17) -> 15 | R17: =IFERROR(IF(VLOOKUP(M17,M35:T47,8,FALSE)="",D37,VLOOKUP(M17,M35:T47,8,FALSE)),NETWORKDAYS.INTL(A3,DATE(YEAR(A3),MONTH(A3)+1,1)-1,1,Sayfa2!C2:C30)*7) -> 154 | S17: =(N17*12)+(O17*12)+(P17*7) -> 180 | T17: =IF(S17-R17<0,0,(S17-R17)) -> 26
A18: =IF(MONTH(A17+1)=MONTH(A17),A17+1,IF(MONTH(A17)+1<=12,DATE(YEAR(A17),MONTH(A17)+1,1),DATE(YEAR(A17)+1,1,1))) -> 45854 | B18: =TEXT(A18,"gggg") -> Çarşamba | C18: Hasan Taş | D18: Cemil Oğuzcan | E18: Emine İnan | F18: İsmail Sarıgüzel | G18: Hasan Taş | H18: Cemil Oğuzcan | I18: Emine İnan | J18: İsmail Sarıgüzel | K18: Arzu Şahin | M18: Fatih Işık | N18: =COUNTIF(C3:F33,M18) -> 3 | O18: =COUNTIF(G3:J33,M18) -> 3 | P18: =COUNTIF(K3:K33,M18) -> 1 | Q18: =((N18+O18)+P18) -> 7 | R18: =IFERROR(IF(VLOOKUP(M18,M35:T47,8,FALSE)="",D37,VLOOKUP(M18,M35:T47,8,FALSE)),NETWORKDAYS.INTL(A3,DATE(YEAR(A3),MONTH(A3)+1,1)-1,1,Sayfa2!C2:C30)*7) -> 77 | S18: =(N18*12)+(O18*12)+(P18*7) -> 79 | T18: =IF(S18-R18<0,0,(S18-R18)) -> 2
A19: =IF(MONTH(A18+1)=MONTH(A18),A18+1,IF(MONTH(A18)+1<=12,DATE(YEAR(A18),MONTH(A18)+1,1),DATE(YEAR(A18)+1,1,1))) -> 45855 | B19: =TEXT(A19,"gggg") -> Perşembe | C19: Muhammet Tonkal | D19: Selin Dal | E19: Hakkı Tuncer | F19: Tuğçe Çalıkoğlu Eski | G19: Muhammet Tonkal | H19: Deniz Aslan | I19: Hakkı Tuncer | J19: Tuğçe Çalıkoğlu Eski | K19: Arzu Şahin | M19: Tuğçe Çalıkoğlu Eski | N19: =COUNTIF(C3:F33,M19) -> 5 | O19: =COUNTIF(G3:J33,M19) -> 5 | P19: =COUNTIF(K3:K33,M19) -> 0 | Q19: =((N19+O19)+P19) -> 10 | R19: =IFERROR(IF(VLOOKUP(M19,M35:T47,8,FALSE)="",D37,VLOOKUP(M19,M35:T47,8,FALSE)),NETWORKDAYS.INTL(A3,DATE(YEAR(A3),MONTH(A3)+1,1)-1,1,Sayfa2!C2:C30)*7) -> 121 | S19: =(N19*12)+(O19*12)+(P19*7) -> 120 | T19: =IF(S19-R19<0,0,(S19-R19)) -> 0
A20: =IF(MONTH(A19+1)=MONTH(A19),A19+1,IF(MONTH(A19)+1<=12,DATE(YEAR(A19),MONTH(A19)+1,1),DATE(YEAR(A19)+1,1,1))) -> 45856 | B20: =TEXT(A20,"gggg") -> Cuma | C20: Burak Şan | D20: Emre T. Şahin | E20: Mehmet Küskü | F20: Melek Ünal | G20: Burak Şan | H20: Ahmet Yılmaz | I20: Mehmet Küskü | J20: Cemil Oğuzcan | K20: Arzu Şahin | M20: Dilek Buzakoğlu | N20: =COUNTIF(C3:F33,M20) -> 5 | O20: =COUNTIF(G3:J33,M20) -> 5 | P20: =COUNTIF(K3:K33,M20) -> 0 | Q20: =((N20+O20)+P20) -> 10 | R20: =IFERROR(IF(VLOOKUP(M20,M35:T47,8,FALSE)="",D37,VLOOKUP(M20,M35:T47,8,FALSE)),NETWORKDAYS.INTL(A3,DATE(YEAR(A3),MONTH(A3)+1,1)-1,1,Sayfa2!C2:C30)*7) -> 119 | S20: =(N20*12)+(O20*12)+(P20*7) -> 120 | T20: =IF(S20-R20<0,0,(S20-R20)) -> 1
A21: =IF(MONTH(A20+1)=MONTH(A20),A20+1,IF(MONTH(A20)+1<=12,DATE(YEAR(A20),MONTH(A20)+1,1),DATE(YEAR(A20)+1,1,1))) -> 45857 | B21: =TEXT(A21,"gggg") -> Cumartesi | C21: Ömer Demir | D21: Şevval Demir | E21: Hakkı Tuncer | F21: Dilek Buzakoğlu | G21: Ömer Demir | H21: Şevval Demir | I21: Hakkı Tuncer | J21: Dilek Buzakoğlu | K21: Hasan Taş | M21: Hasan Taş | N21: =COUNTIF(C3:F33,M21) -> 3 | O21: =COUNTIF(G3:J33,M21) -> 4 | P21: =COUNTIF(K3:K33,M21) -> 2 | Q21: =((N21+O21)+P21) -> 9 | R21: =IFERROR(IF(VLOOKUP(M21,M35:T47,8,FALSE)="",D37,VLOOKUP(M21,M35:T47,8,FALSE)),NETWORKDAYS.INTL(A3,DATE(YEAR(A3),MONTH(A3)+1,1)-1,1,Sayfa2!C2:C30)*7) -> 77 | S21: =(N21*12)+(O21*12)+(P21*7) -> 98 | T21: =IF(S21-R21<0,0,(S21-R21)) -> 21
A22: =IF(MONTH(A21+1)=MONTH(A21),A21+1,IF(MONTH(A21)+1<=12,DATE(YEAR(A21),MONTH(A21)+1,1),DATE(YEAR(A21)+1,1,1))) -> 45858 | B22: =TEXT(A22,"gggg") -> Pazar | C22: Fevzi Karahan | D22: Kübra Gültaş | E22: Emine İnan | F22: Ahmet Yılmaz | G22: Muhammet Tonkal | H22: Kübra Gültaş | I22: Emine İnan | J22: Ahmet Yılmaz | K22: Hasan Taş | M22: Emine İnan | N22: =COUNTIF(C3:F33,M22) -> 8 | O22: =COUNTIF(G3:J34,M22) -> 8 | P22: =COUNTIF(K3:K33,M22) -> 0 | Q22: =((N22+O22)+P22) -> 16 | R22: =IFERROR(IF(VLOOKUP(M22,M35:T47,8,FALSE)="",D37,VLOOKUP(M22,M35:T47,8,FALSE)),NETWORKDAYS.INTL(A3,DATE(YEAR(A3),MONTH(A3)+1,1)-1,1,Sayfa2!C2:C30)*7) -> 154 | S22: =(N22*12)+(O22*12)+(P22*7) -> 192 | T22: =IF(S22-R22<0,0,(S22-R22)) -> 38
A23: =IF(MONTH(A22+1)=MONTH(A22),A22+1,IF(MONTH(A22)+1<=12,DATE(YEAR(A22),MONTH(A22)+1,1),DATE(YEAR(A22)+1,1,1))) -> 45859 | B23: =TEXT(A23,"gggg") -> Pazartesi | C23: Hasan Taş | D23: Deniz Aslan | E23: Hakkı Tuncer | F23: Cemil Oğuzcan | G23: Hasan Taş | H23: Deniz Aslan | I23: Hakkı Tuncer | J23: Cemil Oğuzcan | K23: Arzu Şahin | M23: İsmail Sarıgüzel | N23: =COUNTIF(C3:F33,M23) -> 8 | O23: =COUNTIF(G3:J33,M23) -> 7 | P23: =COUNTIF(K3:K33,M23) -> 1 | Q23: =((N23+O23)+P23) -> 16 | R23: =IFERROR(IF(VLOOKUP(M23,M35:T47,8,FALSE)="",D37,VLOOKUP(M23,M35:T47,8,FALSE)),NETWORKDAYS.INTL(A3,DATE(YEAR(A3),MONTH(A3)+1,1)-1,1,Sayfa2!C2:C30)*7) -> 154 | S23: =(N23*12)+(O23*12)+(P23*7) -> 187 | T23: =IF(S23-R23<0,0,(S23-R23)) -> 33
A24: =IF(MONTH(A23+1)=MONTH(A23),A23+1,IF(MONTH(A23)+1<=12,DATE(YEAR(A23),MONTH(A23)+1,1),DATE(YEAR(A23)+1,1,1))) -> 45860 | B24: =TEXT(A24,"gggg") -> Salı | C24: Selin Dal | D24: Kübra Gültaş | E24: İsmail Sarıgüzel | F24: Mehmet Küskü | G24: Selin Dal | H24: Kübra Gültaş | I24: İsmail Sarıgüzel | J24: Mehmet Küskü | K24: Arzu Şahin | M24: Fevzi Karahan | N24: =COUNTIF(C3:F33,M24) -> 2 | O24: =COUNTIF(G3:J33,M24) -> 0 | P24: =COUNTIF(K3:K33,M24) -> 0 | Q24: =((N24+O24)+P24) -> 2 | R24: =IFERROR(IF(VLOOKUP(M24,M35:T47,8,FALSE)="",D37,VLOOKUP(M24,M35:T47,8,FALSE)),NETWORKDAYS.INTL(A3,DATE(YEAR(A3),MONTH(A3)+1,1)-1,1,Sayfa2!C2:C30)*7) -> 154 | S24: =(N24*12)+(O24*12)+(P24*7) -> 24 | T24: =IF(S24-R24<0,0,(S24-R24)) -> 0
A25: =IF(MONTH(A24+1)=MONTH(A24),A24+1,IF(MONTH(A24)+1<=12,DATE(YEAR(A24),MONTH(A24)+1,1),DATE(YEAR(A24)+1,1,1))) -> 45861 | B25: =TEXT(A25,"gggg") -> Çarşamba | C25: Burak Şan | D25: Deniz Aslan | E25: Hakkı Tuncer | F25: Hasan Taş | G25: Burak Şan | H25: Deniz Aslan | I25: Hakkı Tuncer | J25: Hasan Taş | K25: Arzu Şahin | M25: Arzu Şahin | N25: =COUNTIF(C3:F33,M25) -> 0 | O25: =COUNTIF(G3:J33,M25) -> 0 | P25: =COUNTIF(K3:K33,M25) -> 22 | Q25: =((N25+O25)+P25) -> 22 | R25: =IFERROR(IF(VLOOKUP(M25,M35:T47,8,FALSE)="",D37,VLOOKUP(M25,M35:T47,8,FALSE)),NETWORKDAYS.INTL(A3,DATE(YEAR(A3),MONTH(A3)+1,1)-1,1,Sayfa2!C2:C30)*7) -> 154 | S25: =(N25*12)+(O25*12)+(P25*7) -> 154 | T25: =IF(S25-R25<0,0,(S25-R25)) -> 0
A26: =IF(MONTH(A25+1)=MONTH(A25),A25+1,IF(MONTH(A25)+1<=12,DATE(YEAR(A25),MONTH(A25)+1,1),DATE(YEAR(A25)+1,1,1))) -> 45862 | B26: =TEXT(A26,"gggg") -> Perşembe | C26: Ufuk Aydoğan | D26: Şevval Demir | E26: Emine İnan | F26: Tuğçe Çalıkoğlu Eski | G26: Ufuk Aydoğan | H26: Şevval Demir | I26: Emine İnan | J26: Tuğçe Çalıkoğlu Eski | K26: Arzu Şahin | N26: =COUNTIF(C3:F33,M26) -> 0 | O26: =COUNTIF(G3:J33,M26) -> 0 | P26: =COUNTIF(K3:K33,M26) -> 0 | Q26: =((N26+O26)+P26) -> 0 | R26: =IFERROR(IF(VLOOKUP(M26,M35:T47,8,FALSE)="",D37,VLOOKUP(M26,M35:T47,8,FALSE)),NETWORKDAYS.INTL(A3,DATE(YEAR(A3),MONTH(A3)+1,1)-1,1,Sayfa2!C2:C30)*7) -> 154 | S26: =(N26*12)+(O26*12)+(P26*7) -> 0 | T26: =IF(S26-R26<0,0,(S26-R26)) -> 0
A27: =IF(MONTH(A26+1)=MONTH(A26),A26+1,IF(MONTH(A26)+1<=12,DATE(YEAR(A26),MONTH(A26)+1,1),DATE(YEAR(A26)+1,1,1))) -> 45863 | B27: =TEXT(A27,"gggg") -> Cuma | C27: Muhammet Tonkal | D27: Deniz Aslan | E27: Hakkı Tuncer | F27: Kübra Gültaş | G27: Muhammet Tonkal | H27: Deniz Aslan | I27: Hakkı Tuncer | J27: Kübra Gültaş | K27: Arzu Şahin | N27: =COUNTIF(C3:F33,M27) -> 0 | O27: =COUNTIF(G3:J33,M27) -> 0 | P27: =COUNTIF(K3:K33,M27) -> 0 | Q27: =((N27+O27)+P27) -> 0 | R27: =IFERROR(IF(VLOOKUP(M27,M35:T47,8,FALSE)="",D37,VLOOKUP(M27,M35:T47,8,FALSE)),NETWORKDAYS.INTL(A3,DATE(YEAR(A3),MONTH(A3)+1,1)-1,1,Sayfa2!C2:C30)*7) -> 154 | S27: =(N27*12)+(O27*12)+(P27*7) -> 0 | T27: =IF(S27-R27<0,0,(S27-R27)) -> 0
A28: =IF(MONTH(A27+1)=MONTH(A27),A27+1,IF(MONTH(A27)+1<=12,DATE(YEAR(A27),MONTH(A27)+1,1),DATE(YEAR(A27)+1,1,1))) -> 45864 | B28: =TEXT(A28,"gggg") -> Cumartesi | C28: Ömer Demir | D28: Mehmet Küskü | E28: İsmail Sarıgüzel | F28: Emine İnan | G28: Ömer Demir | H28: Mehmet Küskü | I28: İsmail Sarıgüzel | J28: Emine İnan | K28: Cemil Oğuzcan | N28: =COUNTIF(C4:F34,M28) -> 0 | O28: =COUNTIF(G4:J34,M28) -> 0 | P28: =COUNTIF(K4:K34,M28) -> 0 | Q28: =((N28+O28)+P28) -> 0 | R28: =IFERROR(IF(VLOOKUP(M28,M35:T47,8,FALSE)="",D37,VLOOKUP(M28,M35:T47,8,FALSE)),NETWORKDAYS.INTL(A3,DATE(YEAR(A$3),MONTH(A3)+1,1)-1,1,Sayfa2!C2:C31)*7) -> 154 | S28: =(N28*12)+(O28*12)+(P28*7) -> 0 | T28: =IF(S28-R28<0,0,(S28-R28)) -> 0
A29: =IF(MONTH(A28+1)=MONTH(A28),A28+1,IF(MONTH(A28)+1<=12,DATE(YEAR(A28),MONTH(A28)+1,1),DATE(YEAR(A28)+1,1,1))) -> 45865 | B29: =TEXT(A29,"gggg") -> Pazar | C29: Dilek Buzakoğlu | D29: Ahmet Yılmaz | E29: Hakkı Tuncer | F29: Ufuk Aydoğan | G29: Dilek Buzakoğlu | H29: Ahmet Yılmaz | I29: Hakkı Tuncer | J29: Ufuk Aydoğan | K29: Burak Şan
A30: =IF(MONTH(A29+1)=MONTH(A29),A29+1,IF(MONTH(A29)+1<=12,DATE(YEAR(A29),MONTH(A29)+1,1),DATE(YEAR(A29)+1,1,1))) -> 45866 | B30: =TEXT(A30,"gggg") -> Pazartesi | C30: Mehmet Küskü | D30: Kübra Gültaş | E30: İsmail Sarıgüzel | F30: Cemil Oğuzcan | G30: Mehmet Küskü | H30: Kübra Gültaş | I30: İsmail Sarıgüzel | J30: Cemil Oğuzcan | K30: Arzu Şahin
A31: =IF(MONTH(A30+1)=MONTH(A30),A30+1,IF(MONTH(A30)+1<=12,DATE(YEAR(A30),MONTH(A30)+1,1),DATE(YEAR(A30)+1,1,1))) -> 45867 | B31: =TEXT(A31,"gggg") -> Salı | C31: Selin Dal | D31: Ömer Demir | E31: Emine İnan | F31: Hakkı Tuncer | G31: Selin Dal | H31: Ömer Demir | I31: Emine İnan | J31: Hakkı Tuncer | K31: Arzu Şahin
A32: =IF(MONTH(A31+1)=MONTH(A31),A31+1,IF(MONTH(A31)+1<=12,DATE(YEAR(A31),MONTH(A31)+1,1),DATE(YEAR(A31)+1,1,1))) -> 45868 | B32: =TEXT(A32,"gggg") -> Çarşamba | C32: Burak Şan | D32: Emre T. Şahin | E32: Ahmet Yılmaz | F32: Mehmet Küskü | G32: Burak Şan | H32: Emre T. Şahin | I32: Ahmet Yılmaz | J32: Mehmet Küskü | K32: Arzu Şahin | M32: İZİNLER
A33: =IF(MONTH(A32+1)=MONTH(A32),A32+1,IF(MONTH(A32)+1<=12,DATE(YEAR(A32),MONTH(A32)+1,1),DATE(YEAR(A32)+1,1,1))) -> 45869 | B33: =TEXT(A33,"gggg") -> Perşembe | C33: Ömer Demir | D33: Kübra Gültaş | E33: Melek Ünal | F33: İsmail Sarıgüzel | G33: Ömer Demir | H33: Kübra Gültaş | I33: Melek Ünal | J33: Hasan Taş | K33: Arzu Şahin | M33: Ad Soyad | N33: İzin Başlama | P33: İzin Gün Sayısı | Q33: İş Başı | R33: İzin Tipi | S33: Kalan Gün | T33: Kalan Saat
M35: Deniz Aslan | N35: 45839 | P35: 14 | Q35: =N35+P35 -> 45853 | S35: =D36-NETWORKDAYS.INTL(N35,Q35,1,Sayfa2!C2:C29) -> 12 | T35: =S35*7 -> 84
A36: Aylık Çalışma Gün Sayısı | D36: =NETWORKDAYS.INTL(A3,DATE(YEAR(A3),MONTH(A3)+1,1)-1,1,Sayfa2!C2:C30) -> 22 | M36: Fatih Işık | N36: 45848 | P36: 15 | Q36: =N36+P36 -> 45863 | S36: =D36-NETWORKDAYS.INTL(N36,Q36,1,Sayfa2!C2:C30) -> 11 | T36: =S36*7 -> 77
A37: Aylık Çalışama Saati | D37: =D36*7 -> 154 | M37: Muhammet Tonkal | N37: 45865 | P37: 3 | Q37: =N37+P37 -> 45868 | S37: =D36-NETWORKDAYS.INTL(N37,Q37,1,Sayfa2!C2:C30) -> 19 | T37: =S37*7 -> 133
M38: Burak Şan | N38: 45839 | P38: 10 | Q38: =N38+P38 -> 45849 | S38: =D36-NETWORKDAYS.INTL(N38,Q38,1,Sayfa2!C2:C31) -> 13 | T38: =S38*7 -> 91
M39: Hasan Taş | N39: 45839 | P39: 15 | Q39: =N39+P39 -> 45854 | S39: =D36-NETWORKDAYS.INTL(N39,Q39,1,Sayfa2!C2:C32) -> 11 | T39: =S39*7 -> 77
M40: Dilek Buzakoğlu | N40: 45857 | P40: 7 | Q40: =N40+P40 -> 45864 | S40: =D36-NETWORKDAYS.INTL(N40,Q40,1,Sayfa2!C2:C29) -> 17 | T40: =S40*7 -> 119
Q41: =N41+P41 -> 0 | S41: =D36-NETWORKDAYS.INTL(N41,Q41,1,Sayfa2!C2:C34) -> 22 | T41: =S41*7 -> 154
...
