Workbook

Sheet Personel
A1: KimlikNo | B1: AdSoyad | C1: DogumYeri | D1: DogumTarihi | E1: HizmetSinifi | F1: KadroUnvani | G1: GorevYeri | H1: KurumSicilNo | I1: MemuriyeteBaslamaTarihi | J1: CepTelefonu | K1: Eposta | L1: MezunOlunanOkul | M1: MezunOlunanFakulte | N1: MezuniyetTarihi | O1: DiplomaNo | P1: MezunOlunanOkul2 | Q1: MezunOlunanFakulte2 | R1: MezuniyetTarihi2 | S1: DiplomaNo2 | T1: Resim | U1: Diploma1 | V1: Diploma2 | W1: OzlukDosyasi | X1: Durum | Y1: AyrilisTarihi | Z1: AyrilmaNedeni | AA1: MuayeneTarihi | AB1: Sonuc | AC1: sync_status | AD1: updated_at
A2: 30616959560 | B2: Abdullah Onur Kılıç | C2: =VLOOKUP(Personel!A2,denem!A:AC,8,0) -> #N/A | D2: =VLOOKUP(Personel!A2,denem!A:AC,9,0) -> #N/A | F2: Araştırma Görevlisi (Kurum Dışı) | H2: #N/A | I2: #N/A | K2: #N/A | L2: =PROPER(VLOOKUP(Personel!A2,denem!A:AC,10,0)) -> #N/A | M2: =PROPER(VLOOKUP(Personel!A2,denem!A:AC,11,0)) -> #N/A | N2: =VLOOKUP(Personel!A2,denem!A:AC,12,0) -> #N/A | O2: =PROPER(VLOOKUP(Personel!A2,denem!A:AC,13,0)) -> #N/A | X2: Aktif | AC2: clean
A3: 18199300764 | B3: Abdurrahman Avcıoğlu | C3: =VLOOKUP(Personel!A3,denem!A:AC,8,0) -> Afyonkarahisar | D3: =VLOOKUP(Personel!A3,denem!A:AC,9,0) -> 35661 | F3: Araştırma Görevlisi (Kurum Dışı) | H3: #N/A | I3: #N/A | K3: aavcioglu97@gmail.com | L3: =PROPER(VLOOKUP(Personel!A3,denem!A:AC,10,0)) -> İstanbul Üniversitesi | M3: =PROPER(VLOOKUP(Personel!A3,denem!A:AC,11,0)) -> Cerrahpaşa Tıp Fakültesi | N3: =VLOOKUP(Personel!A3,denem!A:AC,12,0) -> 44554 | O3: =PROPER(VLOOKUP(Personel!A3,denem!A:AC,13,0)) -> 244963 | X3: Aktif | AC3: clean
A4: 27274354172 | B4: Abidin Önder Dönmez | C4: =VLOOKUP(Personel!A4,denem!A:AC,8,0) -> Yeşilova | D4: =VLOOKUP(Personel!A4,denem!A:AC,9,0) -> 26299 | F4: Sağlık Teknikeri | H4: 4209-5297 | I4: 34701 | K4: onderdonmez15@gmail.com | L4: =PROPER(VLOOKUP(Personel!A4,denem!A:AC,10,0)) -> İst. Üni. | M4: =PROPER(VLOOKUP(Personel!A4,denem!A:AC,11,0)) -> Sağ. Hiz. Mes. Yo Radyoloji Bölümü | N4: =VLOOKUP(Personel!A4,denem!A:AC,12,0) -> 34684 | O4: =PROPER(VLOOKUP(Personel!A4,denem!A:AC,13,0)) -> 185 | X4: Aktif | AC4: clean
A5: 18632783390 | B5: Ahmet Bayrak | C5: =VLOOKUP(Personel!A5,denem!A:AC,8,0) -> #N/A | D5: =VLOOKUP(Personel!A5,denem!A:AC,9,0) -> #N/A | F5: Diğer Personel (Ş) | H5: #N/A | I5: #N/A | K5: #N/A | L5: =PROPER(VLOOKUP(Personel!A5,denem!A:AC,10,0)) -> #N/A | M5: =PROPER(VLOOKUP(Personel!A5,denem!A:AC,11,0)) -> #N/A | N5: =VLOOKUP(Personel!A5,denem!A:AC,12,0) -> #N/A | O5: =PROPER(VLOOKUP(Personel!A5,denem!A:AC,13,0)) -> #N/A | X5: Aktif | AC5: clean
A6: 19645682168 | B6: Ahmet Yılmaz | C6: =VLOOKUP(Personel!A6,denem!A:AC,8,0) -> Kaldırımbaşı | D6: =VLOOKUP(Personel!A6,denem!A:AC,9,0) -> 26055 | F6: Laborant | H6: 4149-7113 | I6: 35100 | K6: ahmetyilmazin@gmail.com | L6: =PROPER(VLOOKUP(Personel!A6,denem!A:AC,10,0)) -> İstanbul Üniversitesi | M6: =PROPER(VLOOKUP(Personel!A6,denem!A:AC,11,0)) -> Sağ. Hiz. Mes. Yo Radyoloji Bölümü | N6: =VLOOKUP(Personel!A6,denem!A:AC,12,0) -> 34942 | O6: =PROPER(VLOOKUP(Personel!A6,denem!A:AC,13,0)) -> 241 | X6: Aktif | AC6: clean
A7: 22028017990 | B7: Alperen Kantarcılar | C7: =VLOOKUP(Personel!A7,denem!A:AC,8,0) -> #N/A | D7: =VLOOKUP(Personel!A7,denem!A:AC,9,0) -> #N/A | F7: Hastabakıcı | H7: #N/A | I7: #N/A | K7: #N/A | L7: =PROPER(VLOOKUP(Personel!A7,denem!A:AC,10,0)) -> #N/A | M7: =PROPER(VLOOKUP(Personel!A7,denem!A:AC,11,0)) -> #N/A | N7: =VLOOKUP(Personel!A7,denem!A:AC,12,0) -> #N/A | O7: =PROPER(VLOOKUP(Personel!A7,denem!A:AC,13,0)) -> #N/A | X7: Aktif | AC7: clean
A8: 30872319092 | B8: Arife Tanrıverdi | C8: =VLOOKUP(Personel!A8,denem!A:AC,8,0) -> #N/A | D8: =VLOOKUP(Personel!A8,denem!A:AC,9,0) -> #N/A | F8: Bilgisayar İşletmeni | H8: #N/A | I8: #N/A | K8: #N/A | L8: =PROPER(VLOOKUP(Personel!A8,denem!A:AC,10,0)) -> #N/A | M8: =PROPER(VLOOKUP(Personel!A8,denem!A:AC,11,0)) -> #N/A | N8: =VLOOKUP(Personel!A8,denem!A:AC,12,0) -> #N/A | O8: =PROPER(VLOOKUP(Personel!A8,denem!A:AC,13,0)) -> #N/A | X8: Aktif | AC8: clean
A9: 31621815018 | B9: Artür Salmaslıoğlu | C9: =VLOOKUP(Personel!A9,denem!A:AC,8,0) -> İstanbul | D9: =VLOOKUP(Personel!A9,denem!A:AC,9,0) -> 28024 | F9: Profesör | H9: #N/A | I9: #N/A | K9: asalmaslioglu@gmail.com | L9: =PROPER(VLOOKUP(Personel!A9,denem!A:AC,10,0)) -> İstanbul Üniversitesi | M9: =PROPER(VLOOKUP(Personel!A9,denem!A:AC,11,0)) -> İstanbul Tıp Fakültesi | N9: =VLOOKUP(Personel!A9,denem!A:AC,12,0) -> 37043 | O9: =PROPER(VLOOKUP(Personel!A9,denem!A:AC,13,0)) -> 24838-28306 | X9: Aktif | AC9: clean
A10: 25364482644 | B10: Arzu Çelik | C10: =VLOOKUP(Personel!A10,denem!A:AC,8,0) -> Samsun | D10: =VLOOKUP(Personel!A10,denem!A:AC,9,0) -> 32686 | F10: Sağlık Teknikeri | H10: 4209-7299 | I10: 41562 | K10: arzuozercelik@gmail.com | L10: =PROPER(VLOOKUP(Personel!A10,denem!A:AC,10,0)) -> İstanbul Üniversitesi | M10: =PROPER(VLOOKUP(Personel!A10,denem!A:AC,11,0)) -> Sağ. Hiz. Mes. Yo Radyoloji Bölümü | N10: =VLOOKUP(Personel!A10,denem!A:AC,12,0) -> 40164 | O10: =PROPER(VLOOKUP(Personel!A10,denem!A:AC,13,0)) -> 1903 | X10: Aktif | AC10: clean
A11: 41281522522 | B11: Arzu Poyanlı | C11: =VLOOKUP(Personel!A11,denem!A:AC,8,0) -> 0 | D11: =VLOOKUP(Personel!A11,denem!A:AC,9,0) -> 26055 | F11: Profesör | H11: #N/A | I11: #N/A | K11: arzupoyanli@yahoo.com | L11: =PROPER(VLOOKUP(Personel!A11,denem!A:AC,10,0)) -> İstanbul Üniversitesi | M11: =PROPER(VLOOKUP(Personel!A11,denem!A:AC,11,0)) -> İstanbul Tıp Fakültesi | N11: =VLOOKUP(Personel!A11,denem!A:AC,12,0) -> 34180 | O11: =PROPER(VLOOKUP(Personel!A11,denem!A:AC,13,0)) -> 21852/25320 | X11: Aktif | AC11: clean
A12: 21521659898 | B12: Arzu Şahin | C12: =VLOOKUP(Personel!A12,denem!A:AC,8,0) -> Tokat | D12: =VLOOKUP(Personel!A12,denem!A:AC,9,0) -> 30109 | F12: Sağlık Teknikeri | H12: 4209-7346 | I12: 41562 | K12: elifarzu.1982@gmail.com | L12: =PROPER(VLOOKUP(Personel!A12,denem!A:AC,10,0)) -> Ankara Üniversitesi | M12: =PROPER(VLOOKUP(Personel!A12,denem!A:AC,11,0)) -> Sağ. Hiz. Mes. Yo Radyoloji Bölümü | N12: =VLOOKUP(Personel!A12,denem!A:AC,12,0) -> 37476 | O12: =PROPER(VLOOKUP(Personel!A12,denem!A:AC,13,0)) -> 1933 | X12: Aktif | AC12: clean
A13: 21521169366 | B13: Arzu Burcu Yılmaz | C13: =VLOOKUP(Personel!A13,denem!A:AC,8,0) -> #N/A | D13: =VLOOKUP(Personel!A13,denem!A:AC,9,0) -> #N/A | F13: Diğer Personel (Ş) | H13: #N/A | I13: #N/A | K13: #N/A | L13: =PROPER(VLOOKUP(Personel!A13,denem!A:AC,10,0)) -> #N/A | M13: =PROPER(VLOOKUP(Personel!A13,denem!A:AC,11,0)) -> #N/A | N13: =VLOOKUP(Personel!A13,denem!A:AC,12,0) -> #N/A | O13: =PROPER(VLOOKUP(Personel!A13,denem!A:AC,13,0)) -> #N/A | X13: Aktif | AC13: clean
A14: 38554317466 | B14: Atadan Tunacı | C14: =VLOOKUP(Personel!A14,denem!A:AC,8,0) -> 0 | D14: =VLOOKUP(Personel!A14,denem!A:AC,9,0) -> 23965 | F14: Profesör | H14: #N/A | I14: #N/A | K14: ATATUNA@GMAIL.COM | L14: =PROPER(VLOOKUP(Personel!A14,denem!A:AC,10,0)) -> İstanbul Üniversitesi | M14: =PROPER(VLOOKUP(Personel!A14,denem!A:AC,11,0)) -> İstanbul Tıp Fakültesi | N14: =VLOOKUP(Personel!A14,denem!A:AC,12,0) -> 32143 | O14: =PROPER(VLOOKUP(Personel!A14,denem!A:AC,13,0)) | X14: Aktif | AC14: clean
A15: 43009257976 | B15: Ayhan Açar | C15: =VLOOKUP(Personel!A15,denem!A:AC,8,0) -> #N/A | D15: =VLOOKUP(Personel!A15,denem!A:AC,9,0) -> #N/A | F15: Büro Personeli (Sözleşmeli) | H15: #N/A | I15: #N/A | K15: #N/A | L15: =PROPER(VLOOKUP(Personel!A15,denem!A:AC,10,0)) -> #N/A | M15: =PROPER(VLOOKUP(Personel!A15,denem!A:AC,11,0)) -> #N/A | N15: =VLOOKUP(Personel!A15,denem!A:AC,12,0) -> #N/A | O15: =PROPER(VLOOKUP(Personel!A15,denem!A:AC,13,0)) -> #N/A | X15: Aktif | AC15: clean
A16: 67864076688 | B16: Ayhan Arslanoğlu | C16: =VLOOKUP(Personel!A16,denem!A:AC,8,0) -> Ankara | D16: =VLOOKUP(Personel!A16,denem!A:AC,9,0) -> 27884 | F16: Sağlık Teknikeri | H16: 4209-6130 | I16: 37937 | K16: ayhan.arslanoglu@istabul.edu.tr | L16: =PROPER(VLOOKUP(Personel!A16,denem!A:AC,10,0)) -> Gazi Üniversitesi | M16: =PROPER(VLOOKUP(Personel!A16,denem!A:AC,11,0)) -> Sağ. Hiz. Mes. Yo Radyoloji Bölümü | N16: =VLOOKUP(Personel!A16,denem!A:AC,12,0) -> 35450 | O16: =PROPER(VLOOKUP(Personel!A16,denem!A:AC,13,0)) -> 94102 | X16: Aktif | AC16: clean
A17: 37537744404 | B17: Ayhan Çatkın | C17: =VLOOKUP(Personel!A17,denem!A:AC,8,0) -> #N/A | D17: =VLOOKUP(Personel!A17,denem!A:AC,9,0) -> #N/A | F17: Hastabakıcı | H17: #N/A | I17: #N/A | K17: #N/A | L17: =PROPER(VLOOKUP(Personel!A17,denem!A:AC,10,0)) -> #N/A | M17: =PROPER(VLOOKUP(Personel!A17,denem!A:AC,11,0)) -> #N/A | N17: =VLOOKUP(Personel!A17,denem!A:AC,12,0) -> #N/A | O17: =PROPER(VLOOKUP(Personel!A17,denem!A:AC,13,0)) -> #N/A | X17: Aktif | AC17: clean
A18: 99249933514 | B18: Ayshan Safaralıyeva | C18: =VLOOKUP(Personel!A18,denem!A:AC,8,0) -> #N/A | D18: =VLOOKUP(Personel!A18,denem!A:AC,9,0) -> #N/A | F18: Uzmanlık Öğrencisi Doktor | H18: #N/A | I18: #N/A | K18: #N/A | L18: =PROPER(VLOOKUP(Personel!A18,denem!A:AC,10,0)) -> #N/A | M18: =PROPER(VLOOKUP(Personel!A18,denem!A:AC,11,0)) -> #N/A | N18: =VLOOKUP(Personel!A18,denem!A:AC,12,0) -> #N/A | O18: =PROPER(VLOOKUP(Personel!A18,denem!A:AC,13,0)) -> #N/A | X18: Aktif | AC18: clean
A19: 37745020840 | B19: Ayşin Gül | C19: =VLOOKUP(Personel!A19,denem!A:AC,8,0) -> #N/A | D19: =VLOOKUP(Personel!A19,denem!A:AC,9,0) -> #N/A | F19: Araştırma Görevlisi (Kurum Dışı) | H19: #N/A | I19: #N/A | K19: #N/A | L19: =PROPER(VLOOKUP(Personel!A19,denem!A:AC,10,0)) -> #N/A | M19: =PROPER(VLOOKUP(Personel!A19,denem!A:AC,11,0)) -> #N/A | N19: =VLOOKUP(Personel!A19,denem!A:AC,12,0) -> #N/A | O19: =PROPER(VLOOKUP(Personel!A19,denem!A:AC,13,0)) -> #N/A | X19: Aktif | AC19: clean
A20: 47245166252 | B20: Banu İşcan | C20: =VLOOKUP(Personel!A20,denem!A:AC,8,0) -> #N/A | D20: =VLOOKUP(Personel!A20,denem!A:AC,9,0) -> #N/A | F20: Diğer Personel (Ş) | H20: #N/A | I20: #N/A | K20: #N/A | L20: =PROPER(VLOOKUP(Personel!A20,denem!A:AC,10,0)) -> #N/A | M20: =PROPER(VLOOKUP(Personel!A20,denem!A:AC,11,0)) -> #N/A | N20: =VLOOKUP(Personel!A20,denem!A:AC,12,0) -> #N/A | O20: =PROPER(VLOOKUP(Personel!A20,denem!A:AC,13,0)) -> #N/A | X20: Aktif | AC20: clean
A21: 21661184694 | B21: Banu Solak | C21: =VLOOKUP(Personel!A21,denem!A:AC,8,0) -> Balıkesir | D21: =VLOOKUP(Personel!A21,denem!A:AC,9,0) -> 35296 | F21: Araştırma Görevlisi | H21: #N/A | I21: #N/A | K21: banu.solak@istanbul.edu.tr | L21: =PROPER(VLOOKUP(Personel!A21,denem!A:AC,10,0)) -> İstanbul Üniversitesi | M21: =PROPER(VLOOKUP(Personel!A21,denem!A:AC,11,0)) -> İstanbul Tıp Fakültesi | N21: =VLOOKUP(Personel!A21,denem!A:AC,12,0) -> 44024 | O21: =PROPER(VLOOKUP(Personel!A21,denem!A:AC,13,0)) -> 31987/35455 | X21: Aktif | AC21: clean
A22: 16105981854 | B22: Barış Bakır | C22: =VLOOKUP(Personel!A22,denem!A:AC,8,0) -> Erzurum | D22: =VLOOKUP(Personel!A22,denem!A:AC,9,0) -> 27241 | F22: Profesör | H22: #N/A | I22: #N/A | K22: drbarisbakir@yahoo.com | L22: =PROPER(VLOOKUP(Personel!A22,denem!A:AC,10,0)) -> Ankara Üniversitesi | M22: =PROPER(VLOOKUP(Personel!A22,denem!A:AC,11,0)) -> Tıp Fakültesi | N22: =VLOOKUP(Personel!A22,denem!A:AC,12,0) -> 36780 | O22: =PROPER(VLOOKUP(Personel!A22,denem!A:AC,13,0)) -> 12437 | X22: Aktif | AC22: clean
A23: 37855404714 | B23: Belis Tozlu Yücel | C23: =VLOOKUP(Personel!A23,denem!A:AC,8,0) -> Ordu | D23: =VLOOKUP(Personel!A23,denem!A:AC,9,0) -> 35185 | F23: Araştırma Görevlisi (Kurum Dışı) | H23: #N/A | I23: #N/A | K23: bbelistozlu@gmail.com | L23: =PROPER(VLOOKUP(Personel!A23,denem!A:AC,10,0)) -> Ankara Üniversitesi | M23: =PROPER(VLOOKUP(Personel!A23,denem!A:AC,11,0)) -> Tıp Fakültesi | N23: =VLOOKUP(Personel!A23,denem!A:AC,12,0) -> 44012 | O23: =PROPER(VLOOKUP(Personel!A23,denem!A:AC,13,0)) -> 2020-09-0346 | X23: Aktif | AC23: clean
A24: 42415993164 | B24: Berfim Güngördü | C24: =VLOOKUP(Personel!A24,denem!A:AC,8,0) -> #N/A | D24: =VLOOKUP(Personel!A24,denem!A:AC,9,0) -> #N/A | F24: Ebe | H24: #N/A | I24: #N/A | K24: #N/A | L24: =PROPER(VLOOKUP(Personel!A24,denem!A:AC,10,0)) -> #N/A | M24: =PROPER(VLOOKUP(Personel!A24,denem!A:AC,11,0)) -> #N/A | N24: =VLOOKUP(Personel!A24,denem!A:AC,12,0) -> #N/A | O24: =PROPER(VLOOKUP(Personel!A24,denem!A:AC,13,0)) -> #N/A | X24: Aktif | AC24: clean
A25: 20485675074 | B25: Berna Tomaç | C25: =VLOOKUP(Personel!A25,denem!A:AC,8,0) -> İstanbul | D25: =VLOOKUP(Personel!A25,denem!A:AC,9,0) -> 32898 | F25: Sağlık Teknikeri | H25: 4209-7289 | I25: 40910 | K25: brnolgun_90@hotmail.com | L25: =PROPER(VLOOKUP(Personel!A25,denem!A:AC,10,0)) -> Marmara Üniversitesi | M25: =PROPER(VLOOKUP(Personel!A25,denem!A:AC,11,0)) -> Sağ. Hiz. Mes. Yo Radyoloji Bölümü | N25: =VLOOKUP(Personel!A25,denem!A:AC,12,0) -> 40400 | O25: =PROPER(VLOOKUP(Personel!A25,denem!A:AC,13,0)) -> 547 | X25: Aktif | AC25: clean
A26: 18163287602 | B26: Bilal Karavil | C26: =VLOOKUP(Personel!A26,denem!A:AC,8,0) -> 0 | D26: =VLOOKUP(Personel!A26,denem!A:AC,9,0) -> 36014 | F26: Sağlık Teknisyeni | H26: SZ-3029 | I26: 44075 | K26: bllkrvl26@gmail.com | L26: =PROPER(VLOOKUP(Personel!A26,denem!A:AC,10,0)) -> Eskişehir Osmangazi Üniversitesi | M26: =PROPER(VLOOKUP(Personel!A26,denem!A:AC,11,0)) -> Sağ. Hiz. Mes. Yo Radyoloji Bölümü | N26: =VLOOKUP(Personel!A26,denem!A:AC,12,0) -> 43873 | O26: =PROPER(VLOOKUP(Personel!A26,denem!A:AC,13,0)) -> 165771 | X26: Aktif | AC26: clean
A27: 40423668340 | B27: Bilgin Coşkun | C27: =VLOOKUP(Personel!A27,denem!A:AC,8,0) -> #N/A | D27: =VLOOKUP(Personel!A27,denem!A:AC,9,0) -> #N/A | F27: Bilgisayar İşletmeni | H27: #N/A | I27: #N/A | K27: #N/A | L27: =PROPER(VLOOKUP(Personel!A27,denem!A:AC,10,0)) -> #N/A | M27: =PROPER(VLOOKUP(Personel!A27,denem!A:AC,11,0)) -> #N/A | N27: =VLOOKUP(Personel!A27,denem!A:AC,12,0) -> #N/A | O27: =PROPER(VLOOKUP(Personel!A27,denem!A:AC,13,0)) -> #N/A | X27: Aktif | AC27: clean
A28: 14522068356 | B28: Birsen Gença | C28: =VLOOKUP(Personel!A28,denem!A:AC,8,0) -> Silivri | D28: =VLOOKUP(Personel!A28,denem!A:AC,9,0) -> 27576 | F28: Laborant | H28: #N/A | I28: #N/A | K28: birsenfirat99@gmail.com | L28: =PROPER(VLOOKUP(Personel!A28,denem!A:AC,10,0)) -> Uludağ Üniversitesi | M28: =PROPER(VLOOKUP(Personel!A28,denem!A:AC,11,0)) -> Bursa Sağ. Hiz. Mes. Yo Radyoloji Bölümü | N28: =VLOOKUP(Personel!A28,denem!A:AC,12,0) -> 34206 | O28: =PROPER(VLOOKUP(Personel!A28,denem!A:AC,13,0)) -> 27211 | X28: Aktif | AC28: clean
A29: 13352305068 | B29: Burak Şan | C29: =VLOOKUP(Personel!A29,denem!A:AC,8,0) -> Kahramanmaraş | D29: =VLOOKUP(Personel!A29,denem!A:AC,9,0) -> 35203 | F29: Sağlık Teknikeri | H29: SZ-3455 | I29: 44760 | K29: buraksann070@gmail.com | L29: =PROPER(VLOOKUP(Personel!A29,denem!A:AC,10,0)) -> Nişantaşı Üniversitesi | M29: =PROPER(VLOOKUP(Personel!A29,denem!A:AC,11,0)) -> Sağ. Hiz. Mes. Yo Radyoloji Bölümü | N29: =VLOOKUP(Personel!A29,denem!A:AC,12,0) -> 42898 | O29: =PROPER(VLOOKUP(Personel!A29,denem!A:AC,13,0)) | X29: Aktif | AC29: clean
A30: 51394625768 | B30: Burcu Günay | C30: =VLOOKUP(Personel!A30,denem!A:AC,8,0) -> #N/A | D30: =VLOOKUP(Personel!A30,denem!A:AC,9,0) -> #N/A | F30: Diğer Personel (Ş) | H30: #N/A | I30: #N/A | K30: #N/A | L30: =PROPER(VLOOKUP(Personel!A30,denem!A:AC,10,0)) -> #N/A | M30: =PROPER(VLOOKUP(Personel!A30,denem!A:AC,11,0)) -> #N/A | N30: =VLOOKUP(Personel!A30,denem!A:AC,12,0) -> #N/A | O30: =PROPER(VLOOKUP(Personel!A30,denem!A:AC,13,0)) -> #N/A | X30: Aktif | AC30: clean
A31: 13117894240 | B31: Caner Varol | C31: =VLOOKUP(Personel!A31,denem!A:AC,8,0) -> Çanakkale | D31: =VLOOKUP(Personel!A31,denem!A:AC,9,0) -> 36266 | F31: Sağlık Teknikeri | H31: SZ-3481 | I31: 44789 | K31: caner-varol@hotmail.com | L31: =PROPER(VLOOKUP(Personel!A31,denem!A:AC,10,0)) -> Ege Üniversitesi | M31: =PROPER(VLOOKUP(Personel!A31,denem!A:AC,11,0)) -> Atatürk Sağ. Hiz. Mes. Yo Radyoloji Bölümü | N31: =VLOOKUP(Personel!A31,denem!A:AC,12,0) -> 43993 | O31: =PROPER(VLOOKUP(Personel!A31,denem!A:AC,13,0)) | X31: Aktif | AC31: clean
A32: 24359170214 | B32: Celal Caner Ercan | C32: =VLOOKUP(Personel!A32,denem!A:AC,8,0) -> İstanbul | D32: =VLOOKUP(Personel!A32,denem!A:AC,9,0) -> 33348 | F32: Uzman Tabib | H32: #N/A | I32: #N/A | K32: celalcaner@msn.com | L32: =PROPER(VLOOKUP(Personel!A32,denem!A:AC,10,0)) -> İstanbul Üniversitesi | M32: =PROPER(VLOOKUP(Personel!A32,denem!A:AC,11,0)) -> İstanbul Tıp Fakültesi | N32: =VLOOKUP(Personel!A32,denem!A:AC,12,0) -> 42540 | O32: =PROPER(VLOOKUP(Personel!A32,denem!A:AC,13,0)) -> 30093/33561 | X32: Aktif | AC32: clean
A33: 20707846060 | B33: Cemil Oğuzcan | C33: =VLOOKUP(Personel!A33,denem!A:AC,8,0) -> Kemah | D33: =VLOOKUP(Personel!A33,denem!A:AC,9,0) -> 30317 | F33: Sağlık Teknikeri | H33: 4209-7291 | I33: 41562 | K33: cemiloguzcan@hotmail.com | L33: =PROPER(VLOOKUP(Personel!A33,denem!A:AC,10,0)) -> İstanbul Bilim Üniversitesi | M33: =PROPER(VLOOKUP(Personel!A33,denem!A:AC,11,0)) -> Sağ. Hiz. Mes. Yo Radyoloji Bölümü | N33: =VLOOKUP(Personel!A33,denem!A:AC,12,0) -> 39632 | O33: =PROPER(VLOOKUP(Personel!A33,denem!A:AC,13,0)) -> 29 | X33: Aktif | AC33: clean
A34: 30679636910 | B34: Cüneyt Hebip | C34: =VLOOKUP(Personel!A34,denem!A:AC,8,0) -> İstanbul | D34: =VLOOKUP(Personel!A34,denem!A:AC,9,0) -> 33035 | F34: Sağlık Teknisyeni | H34: 4209-7191 | I34: 40910 | K34: cuneyt.hebip@gmail.com | L34: =PROPER(VLOOKUP(Personel!A34,denem!A:AC,10,0)) -> İstanbul Üniversitesi | M34: =PROPER(VLOOKUP(Personel!A34,denem!A:AC,11,0)) -> Sağ. Hiz. Mes. Yo Radyoloji Bölümü | N34: =VLOOKUP(Personel!A34,denem!A:AC,12,0) -> 40728 | O34: =PROPER(VLOOKUP(Personel!A34,denem!A:AC,13,0)) -> 969 | X34: Aktif | AC34: clean
A35: 21871342648 | B35: Çağlar Büyük | C35: =VLOOKUP(Personel!A35,denem!A:AC,8,0) -> #N/A | D35: =VLOOKUP(Personel!A35,denem!A:AC,9,0) -> #N/A | F35: Hemşire | H35: #N/A | I35: #N/A | K35: #N/A | L35: =PROPER(VLOOKUP(Personel!A35,denem!A:AC,10,0)) -> #N/A | M35: =PROPER(VLOOKUP(Personel!A35,denem!A:AC,11,0)) -> #N/A | N35: =VLOOKUP(Personel!A35,denem!A:AC,12,0) -> #N/A | O35: =PROPER(VLOOKUP(Personel!A35,denem!A:AC,13,0)) -> #N/A | X35: Aktif | AC35: clean
A36: 33955916348 | B36: Çiğdem Eren | C36: =VLOOKUP(Personel!A36,denem!A:AC,8,0) -> İzmit | D36: =VLOOKUP(Personel!A36,denem!A:AC,9,0) -> 32919 | F36: Sağlık Teknikeri | H36: 4209-7086 | I36: 40910 | K36: gs.cigdem_90@hotmail.com | L36: =PROPER(VLOOKUP(Personel!A36,denem!A:AC,10,0)) -> İstabul Universitesi | M36: =PROPER(VLOOKUP(Personel!A36,denem!A:AC,11,0)) -> Sağ. Hiz. Mes. Yo Radyoloji Bölümü | N36: =VLOOKUP(Personel!A36,denem!A:AC,12,0) -> 40333 | O36: =PROPER(VLOOKUP(Personel!A36,denem!A:AC,13,0)) -> 907 | X36: Aktif | AC36: clean
A37: 49576468920 | B37: Değer Özcan | C37: =VLOOKUP(Personel!A37,denem!A:AC,8,0) -> #N/A | D37: =VLOOKUP(Personel!A37,denem!A:AC,9,0) -> #N/A | F37: Hemşire | H37: #N/A | I37: #N/A | K37: #N/A | L37: =PROPER(VLOOKUP(Personel!A37,denem!A:AC,10,0)) -> #N/A | M37: =PROPER(VLOOKUP(Personel!A37,denem!A:AC,11,0)) -> #N/A | N37: =VLOOKUP(Personel!A37,denem!A:AC,12,0) -> #N/A | O37: =PROPER(VLOOKUP(Personel!A37,denem!A:AC,13,0)) -> #N/A | X37: Aktif | AC37: clean
A38: 59701516396 | B38: Deniz Aslan | C38: =VLOOKUP(Personel!A38,denem!A:AC,8,0) -> İstanbul | D38: =VLOOKUP(Personel!A38,denem!A:AC,9,0) -> 33095 | F38: Sağlık Teknikeri | H38: 4209-6985 | I38: 40910 | K38: ensalp2018@gmail.com | L38: =PROPER(VLOOKUP(Personel!A38,denem!A:AC,10,0)) -> İstanbul Üniversitesi | M38: =PROPER(VLOOKUP(Personel!A38,denem!A:AC,11,0)) -> Sağ. Hiz. Mes. Yo Radyoloji Bölümü | N38: =VLOOKUP(Personel!A38,denem!A:AC,12,0) -> 40347 | O38: =PROPER(VLOOKUP(Personel!A38,denem!A:AC,13,0)) -> 905 | X38: Aktif | AC38: clean
A39: 33946154308 | B39: Deniz Saliha Sobayapan | C39: =VLOOKUP(Personel!A39,denem!A:AC,8,0) -> #N/A | D39: =VLOOKUP(Personel!A39,denem!A:AC,9,0) -> #N/A | F39: Araştırma Görevlisi (Kurum Dışı) | H39: #N/A | I39: #N/A | K39: #N/A | L39: =PROPER(VLOOKUP(Personel!A39,denem!A:AC,10,0)) -> #N/A | M39: =PROPER(VLOOKUP(Personel!A39,denem!A:AC,11,0)) -> #N/A | N39: =VLOOKUP(Personel!A39,denem!A:AC,12,0) -> #N/A | O39: =PROPER(VLOOKUP(Personel!A39,denem!A:AC,13,0)) -> #N/A | X39: Aktif | AC39: clean
A40: 28762644492 | B40: Dilek Buzakoğlu | C40: =VLOOKUP(Personel!A40,denem!A:AC,8,0) -> #N/A | D40: =VLOOKUP(Personel!A40,denem!A:AC,9,0) -> #N/A | F40: Sağlık Teknikeri | H40: 4209-7210 | I40: 40914 | K40: #N/A | L40: =PROPER(VLOOKUP(Personel!A40,denem!A:AC,10,0)) -> #N/A | M40: =PROPER(VLOOKUP(Personel!A40,denem!A:AC,11,0)) -> #N/A | N40: =VLOOKUP(Personel!A40,denem!A:AC,12,0) -> #N/A | O40: =PROPER(VLOOKUP(Personel!A40,denem!A:AC,13,0)) -> #N/A | X40: Aktif | AC40: clean
...

Sheet denem
A1: T.C. Kimlik No | B1: Ad Soyad | C1: E-posta Adresi | D1: Vesikalık Fotograf | E1: Unvanı | F1: Görevi | G1: Baba Adı | H1: Doğum Yeri / Tarihi | I1: Sütun1 | J1: Mezun Olduğu Okul / Yüksek Okul / Fakülte | K1: Sütun2 | L1: Diploma Tarih ve No | M1: Sütun4 | N1: Uzmanlık Belgesi Tarih ve No (Varsa)
A2: 27274354172 | B2: A. Önder Dönmez | C2: onderdonmez15@gmail.com | D2: https://Doktorive.google.com/open?id=1xD2OR936EMERrgEFQFK-b6HMxP5Thp0T | E2: Sağlık Teknikeri | F2: Radyoloji Teknikeri | G2: Ömer | H2: Yeşilova | I2: 26299 | J2: İst. Üni. | K2: Sağ. Hiz. Mes. YO Radyoloji Bölümü | L2: 34684 | M2: 185 | N2: ----
A3: 18199300764 | B3: Abdurrahman AVCIOĞLU | C3: aavcioglu97@gmail.com | D3: https://drive.google.com/open?id=1FDUcBJxUQtNFjYG5KZplRaWO0P0gVmnr | E3: Asistan Doktor | F3: Doktor | G3: Erkan | H3: Afyonkarahisar | I3: 35661 | J3: İstanbul üniversitesi | K3: Cerrahpaşa tıp fakültesi | L3: 44554 | M3: 244963
A4: 15869294644 | B4: Ahmet Yasin Karkaş | C4: yasinkarkas@gmail.com | D4: https://Doktorive.google.com/open?id=1fvzep5d9sr8lmMeUweX56wmQf1aU02Fi | E4: Araştırma Görevlisi, Doktor | F4: Tıpta Uzmanlık Öğrencisi | G4: Murat | H4: Van | I4: 34419 | J4: İstanbul Üniversitesi | K4: İstanbul Tıp Fakültesi | L4: 43289 | M4: 31304/34772
A5: 19645682168 | B5: Ahmet Yılmaz | C5: ahmetyilmazin@gmail.com | D5: https://drive.google.com/open?id=1820zlQZ0aHnZmE2egFshM3H9XNsYO4t7 | E5: Laborant | F5: Radyoloji teknikeri | G5: Hasan | H5: Kaldırımbaşı | I5: 26055 | J5: İstanbul üniversitesi | K5: Sağ. Hiz. Mes. YO Radyoloji Bölümü | L5: 34942 | M5: 241
A6: 16499844230 | B6: Ali ozan malkoç | C6: aliozanmalkoc@msn.com | D6: https://drive.google.com/open?id=1u_9qOB50KyFNDOLveAa5vEkPPu51IBEV | E6: Radyoloji teknikeri | F6: Sağlık teknikeri | G6: Recep | H6: Bakırköy | I6: 30752 | J6: İstanbul universitesi | K6: Sağ. Hiz. Mes. YO Radyoloji Bölümü | L6: 39267 | M6: 881
A7: 31621815018 | B7: Artür Salmaslıoğlu | C7: asalmaslioglu@gmail.com | D7: https://drive.google.com/open?id=1qD73PTajtE8lmOxl7b91Vig9wH5BY3ms | E7: Prof. Dr. | F7: Radyoloji ABD Doktor | G7: Kevork | H7: İstanbul | I7: 28024 | J7: İstanbul Üniversitesi | K7: İstanbul Tıp Fakültesi | L7: 37043 | M7: 24838-28306 | N7: 16.09.2005 68241
A8: 19277490100 | B8: ARZU AKSÜT | C8: arzuaksut@hotmail.com | D8: https://drive.google.com/open?id=1rPu0Ybrej_LUgLRSsjka3BmxvMhBfD6X | E8: RADYOLOJİ TEKNİKERİ | F8: RADYOLOJİ TEKNİKERİ | G8: CELİL | H8: IĞDIR | J8: MARMARA ÜNİVERSİTESİ | K8: Sağ. Hiz. Mes. YO Radyoloji Bölümü | L8: 33604 | M8: 11
A9: 25364482644 | B9: Arzu Çelik | C9: arzuozercelik@gmail.com | D9: https://Doktorive.google.com/open?id=1zO7IKbY98goYnhlu9w4j_LQPiw-MtYKx | E9: Sağlık Teknikeri | F9: Radyoloji Teknikeri | G9: Hayrettin | H9: Samsun | I9: 32686 | J9: İstanbul Üniversitesi | K9: Sağ. Hiz. Mes. YO Radyoloji Bölümü | L9: 40164 | M9: 1903
A10: 41281522522 | B10: Arzu Poyanlı | C10: arzupoyanli@yahoo.com | D10: https://drive.google.com/open?id=1jiT5uNApBZBcWOk-rGO-18dFspFAO5qz | E10: Prof. Dr | F10: Doktor | G10: Kazım Armağan | I10: 26055 | J10: İstanbul Üniversitesi | K10: İstanbul Tıp Fakültesi | L10: 34180 | M10: 21852/25320 | N10: Uzmanlık tarihi 22.05.1997, tescil: 56011 67805, kayıt tarihi: 07.03.2002
A11: 21521659898 | B11: Arzu Şahin | C11: elifarzu.1982@gmail.com | D11: https://drive.google.com/open?id=16JL5S2aobzBtWJ6m_12Z9d_1MGw-dPZN | E11: Sağlık teknikeri | F11: Radyoloji teknikeri | G11: Cemal | H11: Tokat | I11: 30109 | J11: Ankara üniversitesi | K11: Sağ. Hiz. Mes. YO Radyoloji Bölümü | L11: 37476 | M11: 1933
A12: 38554317466 | B12: ATADAN TUNACI | C12: ATATUNA@GMAIL.COM | D12: https://drive.google.com/open?id=1fGLW-Yp5szAephj-6KgPVD-yavzWNCTR | E12: PROFESÖR DOKTOR | F12: RADYOLOJİ | G12: MEHMET | I12: 23965 | J12: İstanbul Üniversitesi | K12: İstanbul Tıp Fakültesi | L12: 32143
A13: 67864076688 | B13: Ayhan Arslanoglu | C13: ayhan.arslanoglu@istabul.edu.tr | D13: https://drive.google.com/open?id=158dQb5WFZqBjP6X_jBW1JdKpw_ak9Udt | E13: Sağlık Teknikeri | F13: Radyoloji teknikeri | G13: Hüseyin Fikri | H13: Ankara | I13: 27884 | J13: Gazi üniversitesi | K13: Sağ. Hiz. Mes. YO Radyoloji Bölümü | L13: 35450 | M13: 94102
A14: 18418193320 | B14: Ayşe İbiş | C14: ayseibis@istanbul.edu.tr | D14: https://drive.google.com/open?id=183loTrCwbRoXE1qJ4qvJgodef0zkfItI | E14: Araştırma Görevlisi | F14: Doktor | G14: Ömer | H14: Besni | I14: 33551 | J14: Çukurova Üniversitesi | K14: Tıp Fakültesi | L14: 42005 | M14: 176614
A15: 21661184694 | B15: Banu Solak | C15: banu.solak@istanbul.edu.tr | D15: https://Doktorive.google.com/open?id=1UGO-2JO7IM6oZi_hi6rhbskFCoPSYK4f | E15: Uzmanlık Öğrencisi | F15: Asistan doktor | G15: Hikmet | H15: Balıkesir | I15: 35296 | J15: İstanbul üniversitesi | K15: İstanbul Tıp Fakültesi | L15: 44024 | M15: 31987/35455
A16: 16105981854 | B16: BARIŞ BAKIR | C16: drbarisbakir@yahoo.com | D16: https://drive.google.com/open?id=1VS-h05Fid-Hv9IhnJh5OX7NLMaOnUQTA | E16: Profesör | F16: Radyoloji Uzmanı | G16: Zeki | H16: Erzurum | I16: 27241 | J16: Ankara Üniversitesi | K16: Tıp Fakültesi | L16: 36780 | M16: 12437 | N16: 21/10/2004 75867
A17: 37855404714 | B17: Belis Tozlu | C17: bbelistozlu@gmail.com | D17: https://drive.google.com/open?id=1Yp4VgQ2ek-iKXFBgnUvjr42MbzbDIchT | E17: Asistan Doktor | F17: Doktor | G17: Zafer | H17: Ordu | I17: 35185 | J17: Ankara Üniversitesi | K17: Tıp Fakültesi | L17: 44012 | M17: 2020-09-0346
A18: 16673314078 | B18: Berke Ersoy | C18: berke.ersoy@istanbul.edu.tr | D18: https://Doktorive.google.com/open?id=1jLozGU4VH4qixAfJNInsg-GumtLUmcGi | E18: Tıpta Uzmanlık Öğrencisi | F18: Doktor | G18: Muzaffer | H18: İstanbul | I18: 33970 | J18: İstanbul üniversitesi | K18: İstanbul Tıp Fakültesi | L18: 42911 | M18: 34148
A19: 20485675074 | B19: BERNA TOMAÇ | C19: brnolgun_90@hotmail.com | D19: https://drive.google.com/open?id=1A8rIcGpaQrHYDXFBl6NlP0K7nJIdUbK0 | E19: SAĞLIK TEKNİKERİ | F19: RADYOLOJİ TEKNİKERİ | G19: SÜLEYMAN | H19: İstanbul | I19: 32898 | J19: MARMARA ÜNİVERSİTESİ | K19: Sağ. Hiz. Mes. YO Radyoloji Bölümü | L19: 40400 | M19: 547
A20: 18163287602 | B20: Bilal Karavil | C20: bllkrvl26@gmail.com | D20: https://drive.google.com/open?id=1Gn1bHRjhc9v2ugFgI_Rz3l1vfL1iUSBd | E20: Diğer Sağlık Personeli | F20: Radyoloji Teknikeri | G20: Aydın | I20: 36014 | J20: Eskişehir Osmangazi Üniversitesi | K20: Sağ. Hiz. Mes. YO Radyoloji Bölümü | L20: 43873 | M20: 165771
A21: 17270107162 | B21: Bilgin Nabi COŞKUN | C21: bncoskun@istanbul.edu.tr | D21: https://Doktorive.google.com/open?id=1hQUOdbu6qzEYm2PtvnrhU5GaVl6ReEcB | E21: Doktor | F21: Arş.Gör | G21: Erhan | I21: 34152 | J21: Karadeniz Teknik Üniversitesi | K21: Tıp Fakültesi | L21: 42736 | M21: 0601.57
A22: 14522068356 | B22: Birsen Fırat | C22: birsenfirat99@gmail.com | D22: https://drive.google.com/open?id=15Ma7gPrlG2GKIrDICvMdomiTI4GiGbhA | E22: Laborant | F22: Radyoloji teknisyeni | G22: Hüseyin | H22: Silivri | I22: 27576 | J22: Uludağ Üniversitesi | K22: Bursa Sağ. Hiz. Mes. YO Radyoloji Bölümü | L22: 34206 | M22: 27211
A23: 13352305068 | B23: Burak şan | C23: buraksann070@gmail.com | D23: https://Doktorive.google.com/open?id=1XUsbjt7GLstuyztM9nGArMPAVueUW5_r | E23: Radyoloji Teknikeri | F23: Radyoloji Teknikeri | G23: Ejder | H23: Kahramanmaraş | I23: 35203 | J23: Nişantaşı üniversitesi | K23: Sağ. Hiz. Mes. YO Radyoloji Bölümü | L23: 42898
A24: 13856278820 | B24: Bülent Acunaş | C24: acunasb@hotmail.com | D24: https://Doktorive.google.com/open?id=1sRfjLgopLqnpd1yw6ylLEp_FNejt6XrP | E24: Prof. Doktor. | F24: Öğretim Üyesi | G24: Ali | H24: Samsun | I24: 20719 | J24: İstanbul üniversitesi | K24: İstanbul Tıp Fakültesi | L24: 29221 | M24: 19703 | N24: 14.03.1985. 22447
A25: 13117894240 | B25: Caner varol | C25: caner-varol@hotmail.com | D25: https://drive.google.com/open?id=1Eg09th1430UMruQJIlPD_TeI9jRBcDiV | E25: Radyoloji Teknikeri | F25: BT TEKNİKERİ | G25: Mustafa | H25: Çanakkale | I25: 36266 | J25: Ege Üniversitesi | K25: Atatürk Sağ. Hiz. Mes. YO Radyoloji Bölümü | L25: 43993
A26: 24359170214 | B26: Celal Caner Ercan | C26: celalcaner@msn.com | D26: https://Doktorive.google.com/open?id=1VYqmQglbDsYS-trbVPJ9GmsAfYNU3d5C | E26: Doktor | F26: Asistan Doktor | G26: Cevat | H26: İstanbul | I26: 33348 | J26: İstanbul üniversitesi | K26: İstanbul Tıp Fakültesi | L26: 42540 | M26: 30093/33561
A27: 60142116854 | B27: Cem Kara | C27: cem.kara@istanbul.edu.tr | D27: https://drive.google.com/open?id=190nK3W9YoxQ_9HHkcdCkcqyB-4oDa7CQ | E27: Radyoloji Teknikeri | F27: Radyoloji Teknikeri | G27: Şerif | H27: Manisa | I27: 27891 | J27: Marmara Üniversitesi | K27: Sağ. Hiz. Mes. YO Radyoloji Bölümü | L27: 35667 | M27: 140
A28: 20707846060 | B28: cemiloguzcan@hotmail.com | C28: cemiloguzcan@hotmail.com | D28: https://Doktorive.google.com/open?id=16CHIk85DCEFS8lCrO5IORzw6O5ngNbvE | E28: Radyoloji Teknikeri | F28: Acil röntgen | G28: Adil | H28: Kemah | I28: 30317 | J28: İstanbul bilim üniversitesi | K28: Sağ. Hiz. Mes. YO Radyoloji Bölümü | L28: 39632 | M28: 29
A29: 30679636910 | B29: Cüneyt Hebip | C29: cuneyt.hebip@gmail.com | D29: https://drive.google.com/open?id=1OtCfpLLuX5CGDhwCkmYQ9EGEFKXtsINZ | E29: Radyoloji Teknikeri | F29: Radyoloji Teknikeri | G29: Erdoğan | H29: İstanbul | I29: 33035 | J29: İstanbul Üniversitesi | K29: Sağ. Hiz. Mes. YO Radyoloji Bölümü | L29: 40728 | M29: 969
A30: 33955916348 | B30: Çiğdem Eren | C30: gs.cigdem_90@hotmail.com | D30: https://Doktorive.google.com/open?id=1IcpfOs5fXSQVfPWYS_h1lHM-aYNLFj82 | E30: Sağlık Teknikeri | F30: Sağlik Teknikeri | G30: Ergün | H30: İzmit | I30: 32919 | J30: İstabul universitesi | K30: Sağ. Hiz. Mes. YO Radyoloji Bölümü | L30: 40333 | M30: 907
A31: 41098254104 | B31: DAVUD BAHADIR YILDIRIM | C31: bahadiryildir@gmail.con | D31: https://drive.google.com/open?id=1YMZPxoq0KQFr2tzdwXCd-E83EdCZNlpc | E31: Araştırma Görevlisi | F31: Doktor | G31: Nihat | H31: Gaziantep | I31: 34776 | J31: Ankara Üniversitesi | K31: Tıp Fakültesi | L31: 43852 | M31: 2020-09-0049
A32: 59701516396 | B32: Deniz Aslan | C32: ensalp2018@gmail.com | D32: https://drive.google.com/open?id=1_GMXyXHFFpxeJI9flGCyDF45BTf-92C8 | E32: Sağlık Teknikleri | F32: Radyoloji ABD | G32: Şaban | H32: İstanbul | I32: 33095 | J32: İstanbul Üniversitesi | K32: Sağ. Hiz. Mes. YO Radyoloji Bölümü | L32: 40347 | M32: 905
A33: 72499060568 | B33: Edanur Karapınar | C33: edanurkarapinar@istanbul.edu.tr | D33: https://Doktorive.google.com/open?id=15lPgts4bIC7vjZ4j9j54Kz0DeNZ4O7At | E33: Araştırma Görevlisi Doktor | F33: Tıpta uzmanlık öğrencisi | G33: Ertuğrul Halit | H33: İstanbul | I33: 34127 | J33: İstanbul Tıp Fakültesi | K33: İstanbul Tıp Fakültesi | L33: 43492 | M33: 31373/34841
A34: 27259973206 | B34: Ekrem Çok | C34: 34ekremcok@gmail.com | D34: https://drive.google.com/open?id=1F1Ex0dKey_vfPVJI54qnzazVaetPmkNO | E34: Tıbbi Görüntüleme Teknikeri | F34: Tekniker | G34: Nadir | H34: İstanbul | I34: 34340 | J34: Nişantaşı Üniversitesi | K34: Tıbbi Görüntüleme M.Y.0
A35: 12247655530 | B35: Elif Şentürk Toraman | C35: Esenturk1403@gmail.com | D35: https://drive.google.com/open?id=12iTJGD_BwIsKj6a0YBqKrxsLdT9nqLpc | E35: Sağlık Teknikeri | F35: Radyoloji Teknikeri | G35: Hüseyin | H35: Borçka | I35: 32258 | J35: İstanbul üniversitesi | K35: Sağ. Hiz. Mes. YO Radyoloji Bölümü | L35: 39633 | M35: 841
A36: 31388172744 | B36: Emine İnan | C36: emineinan001@gmail.com | D36: https://drive.google.com/open?id=1dWkOxNYwvqG6S2KgYHB3mv9vgASJF6FX | E36: Teknisyen | F36: Röntgen Teknisyeni | G36: Nezir | H36: Batman | I36: 35432 | J36: İstanbul Medipol Üniversitesi | K36: Sağ. Hiz. Mes. YO Radyoloji Bölümü | L36: 42894 | M36: 17HM0026
A37: 31531851298 | B37: Emre Tolga ŞAHİN | C37: emretolgasahin@hotmail.com | D37: https://drive.google.com/open?id=15XXtbPC72f0bvhcyJlk-pootJ8PiZnAl | E37: Radyoloji teknisyeni | F37: Radyoloji teknisyeni | G37: Hamdi | H37: İstanbul | I37: 31072 | J37: Haydarpaşa Bülent Akarcalı Sağlık Meslek lisesi
A38: 20564739512 | B38: Ercan Hamarat | C38: ercan.na@hotmail.com | D38: https://Doktorive.google.com/open?id=1CfqmjYDTiLJub-FGh6QIalzjbTY32xHK | E38: Radyoloji Teknikeri | F38: Sağlık Teknikeri | G38: Hasan Hamarat | H38: Şanlıurfa | I38: 25934 | J38: Yeni Yüzyıl Üniversitesi | K38: Sağ. Hiz. Mes. YO Radyoloji Bölümü | L38: 35997 | M38: 61
A39: 27422435302 | B39: Erdal | C39: erdalagbulut@gmail.com | D39: https://drive.google.com/open?id=1puD_aX4cGOLS11dLb6w6dujzDLTmLHvU | E39: sağlık teknikeri | F39: radyoloji teknikeri | G39: İSMAİL | H39: KANGAL | I39: 25905 | J39: İstanbul üniversitesi | K39: Sağ. Hiz. Mes. YO Radyoloji Bölümü | L39: 33959 | M39: 99
A40: 56704599364 | B40: Esin korkut | C40: esinduvek@gmail.com | D40: https://Doktorive.google.com/open?id=1UQKD1uO2_ZMmFmk9q28fwC9PXPnR8EIl | E40: Uzman Doktor | F40: Doktor | G40: İbrahim | I40: 33786 | J40: İstanbul üniversitesi | K40: İstanbul Tıp Fakültesi | L40: 42540 | M40: 30186/33654 | N40: 11.11.2022 157274
...

Sheet denem2
A1: T.C. Kimlik No | B1: Çalışanın Adı Soyadı | C1: Kadro Ünvanı | D1: Kadronuzun Bulunduğu Bölüm / ABD | E1: Görev Yeri | F1: Sicil No | G1: Memuriyet Başlama Tarihi:
A2: 27274354172 | B2: Abidin önder dönmez | C2: Sağlık teknikeri | D2: Radyodagnostik ABD | E2: Radyoloji ABD | F2: 4209-5297 | G2: 34701
A3: 19645682168 | B3: Ahmet Yılmaz | C3: Laborant | D3: Çocuk hastalıkları | E3: Acil röntgen | F3: 4149-7113 | G3: 35100
A4: 16499844230 | B4: Ali ozan malkoç | C4: Sağlık teknikeri radyoloji | D4: Radyoloji Anabilim dali | E4: Acil cerrahi rontgen | F4: 4209-7268 | G4: 40545
A5: 19277490100 | B5: Arzu Aksüt | C5: Sağlık teknisyeni | D5: Sağlık kültür spor daire başkanlığı | E5: İtf semt polikliniği | F5: 4200/2371 | G5: 35170
A6: 25364482644 | B6: Arzu Çelik | C6: Sağlık Teknikeri | D6: Mr Bölümü / Radyoloji ABD | E6: İSTANBUL TIP FAKÜLTESİ | F6: 4209-7299 | G6: 41562
A7: 21521659898 | B7: Arzu Şahin | C7: Sağlık Teknikeri | D7: Radyoloji ABD | E7: Radyoloji | F7: 4209-7346 | G7: 41562
A8: 67864076688 | B8: Ayhan Arslanoğlu | C8: Sağlık Teknikeri | D8: RADYODİAĞNOSTİK ABD | E8: Radyoloji Ana Bilim Dalı | F8: 4209-6130 | G8: 37937
A9: 20485675074 | B9: Berna Tomaç | C9: Sağlık Teknikeri | D9: Radyoloji Ana Bilim Dalı | E9: Radyoloji | F9: 4209-7289 | G9: 40910
A10: 18163287602 | B10: Bilal Karavil | C10: Diğer Sağlık Personeli | D10: Radyoloji | E10: Acil Röntgen | F10: SZ-3029 | G10: 44075
A11: 13352305068 | B11: Burak şan | C11: Sağlık teknikeri | D11: Radyoloji | E11: Acil röntgen | F11: SZ-3455 | G11: 44760
A12: 13117894240 | B12: Caner Varol | C12: SAĞLIK TEKNİKERİ | D12: RADYOLOJİ A.B.D | E12: İSTANBUL TIP FAKÜLTESİ BT-1 | F12: SZ-3481 | G12: 44789
A13: 60142116854 | B13: Cem Kara | C13: Sağlık Teknikeri | D13: Radyoloji ABD. | E13: Acil Tomografi | F13: 4209-6919 | G13: 35745
... A63: 21413501298 | B63: Yasa alp | C63: Sağlık teknikeri | D63: Radyoloji | E63: Radyoloji | F63: 4209-6797 | G63: 40168
